#![no_std]
#![no_main]

use error_set::{error_set, CoerceResult, ResultContext};
use core::fmt::Write;


#[no_mangle]
pub extern "C" fn _start() -> ! {
    readme_example();
    display();
    log();
    exit(0);
}


fn exit(code: i32) -> ! {
    unsafe {
        core::arch::asm!(
            "mov rax, 60",
            "mov rdi, {0}",
            "syscall",
            in(reg) code,
            options(noreturn)
        );
    }
}

#[panic_handler]
fn panic(_info: &core::panic::PanicInfo) -> ! {
    exit(1);
}

//************************************************************************//

error_set! {
    MediaError = {
        IoError(self::TestError),
        MissingBookDescription,
        MissingName,
        NoContents,
        InvalidUrl,
        MaximumUploadSizeReached,
        TimedOut,
        AuthenticationFailed,
    };
    BookParsingError = {
        MissingBookDescription,
        CouldNotReadBook(self::TestError),
        MissingName,
        NoContents,
    };
    BookSectionParsingError = {
        MissingName,
        NoContents,
    };
    DownloadError = {
        InvalidUrl,
        CouldNotSaveBook(self::TestError),
    };
    ParseUploadError = {
        MaximumUploadSizeReached,
        TimedOut,
        AuthenticationFailed,
    };
}

pub struct TestError(u32);

impl TestError {
    pub fn new(code: u32) -> Self {
        Self(code)
    }
}

impl core::error::Error for TestError {}

impl core::fmt::Display for TestError {
    fn fmt(&self, f: &mut core::fmt::Formatter) -> core::fmt::Result {
        write!(f, "TestError: {}", self.0)
    }
}

impl core::fmt::Debug for TestError {
    fn fmt(&self, f: &mut core::fmt::Formatter) -> core::fmt::Result {
        write!(f, "TestError: {}", self.0)
    }
}

fn readme_example() {
    let book_section_parsing_error: BookSectionParsingError =
    BookSectionParsingError::MissingName;
    let book_parsing_error: BookParsingError = book_section_parsing_error.into();
    assert!(matches!(book_parsing_error, BookParsingError::MissingName));
    let media_error: MediaError = book_parsing_error.into();
    assert!(matches!(media_error, MediaError::MissingName));

    let io_error = TestError::new(500);
    let result_download_error: Result<(), DownloadError> = Err(io_error).coerce();
    let result_media_error: Result<(), MediaError> = result_download_error.map_err(Into::into);
    assert!(matches!(result_media_error, Err(MediaError::IoError(_))));
}

// //************************************************************************//

error_set! {
    AuthError = {
        A,
        #[display("User `{}` with role `{}` does not exist", name, role)]
        UserDoesNotExist {
            name: u32,
            role: u32,
        },
        #[display("The provided credentials are invalid")]
        InvalidCredentials
    };
    AuthError2 = {
        #[display("User does not exist")]
        UserDoesNotExist {
            name: u32,
            role: u32,
        }
    };
}


fn display() {
    // `heapless` and/or `write!` Seems to always seg fault for some reason. e.g.
    // let mut buf: heapless::String<300> = heapless::String::new();
    // write!(buf, "this").unwrap();

    // let x: AuthError2 = AuthError2::UserDoesNotExist {
    //     name: 1,
    //     role: 30,
    // };
    // let mut buf: heapless::String<300> = heapless::String::new();
    // write!(buf, "{}", x).unwrap();
    // assert_eq!(buf.as_str(), "User does not exist");
    // let x: AuthError = x.into();
    // let mut buf: heapless::String<300> = heapless::String::new();
    // write!(buf, "{}", x).unwrap();
    // assert_eq!(buf.as_str(), "AuthError::UserDoesNotExist");
    // let x: AuthError = AuthError::InvalidCredentials;
    // let mut buf: heapless::String<300> = heapless::String::new();
    // write!(buf, "{}", x).unwrap();
    // assert_eq!(buf.as_str(), "The provided credentials are invalid");
}

//************************************************************************//

fn log() {
    // let x: Result<u32, &str> = Err("error value");
    // x.error("context around");
}